<?xml version="1.0" encoding="utf-8" standalone="no"?>
<!--This file represents the results of running a test suite-->
<test-results name=".\bin\tests.dll" total="5" errors="0" failures="0" not-run="0" inconclusive="0" ignored="0" skipped="0" invalid="0" date="2013-01-30" time="16:55:11">
  <environment nunit-version="2.5.7.10213" clr-version="2.0.50727.4927" os-version="Microsoft Windows NT 6.1.7600.0" platform="Win32NT" cwd="d:\GitHub\Continuations" machine-name="MYEANEY-3261" user="MYeaney" user-domain="COSMO" />
  <culture-info current-culture="en-US" current-uiculture="en-US" />
  <test-suite type="Assembly" name=".\bin\tests.dll" executed="True" result="Success" success="True" time="5.226" asserts="0">
    <results>
      <test-suite type="Namespace" name="Tests" executed="True" result="Success" success="True" time="5.226" asserts="0">
        <results>
          <test-suite type="TestFixture" name="ContinuationTests" executed="True" result="Success" success="True" time="5.226" asserts="0">
            <results>
              <test-case name="Tests.ContinuationTests.CanChainAsyncTasks" executed="True" result="Success" success="True" time="0.109" asserts="0" />
              <test-case name="Tests.ContinuationTests.CanChainTasks" executed="True" result="Success" success="True" time="0.016" asserts="0" />
              <test-case name="Tests.ContinuationTests.CanChainTasksWithoutEndWith" executed="True" result="Success" success="True" time="0.000" asserts="0" />
              <test-case name="Tests.ContinuationTests.CanChainTasksWithoutEndWithAndThrowException" executed="True" result="Success" success="True" time="0.016" asserts="0" />
              <test-case name="Tests.ContinuationTests.CanRetryOperationSpecifiedNumberOfTimes" executed="True" result="Success" success="True" time="5.070" asserts="0" />
            </results>
          </test-suite>
        </results>
      </test-suite>
    </results>
  </test-suite>
</test-results>